[2022-03-18 15:52:19,054] {taskinstance.py:1037} INFO - Dependencies all met for <TaskInstance: udac_example_dag.Run_data_quality_checks scheduled__2022-03-18T06:00:00+00:00 [queued]>
[2022-03-18 15:52:19,063] {taskinstance.py:1037} INFO - Dependencies all met for <TaskInstance: udac_example_dag.Run_data_quality_checks scheduled__2022-03-18T06:00:00+00:00 [queued]>
[2022-03-18 15:52:19,064] {taskinstance.py:1243} INFO - 
--------------------------------------------------------------------------------
[2022-03-18 15:52:19,064] {taskinstance.py:1244} INFO - Starting attempt 1 of 3
[2022-03-18 15:52:19,064] {taskinstance.py:1245} INFO - 
--------------------------------------------------------------------------------
[2022-03-18 15:52:19,072] {taskinstance.py:1264} INFO - Executing <Task(DataQualityOperator): Run_data_quality_checks> on 2022-03-18 06:00:00+00:00
[2022-03-18 15:52:19,075] {standard_task_runner.py:52} INFO - Started process 20812 to run task
[2022-03-18 15:52:19,079] {standard_task_runner.py:76} INFO - Running: ['***', 'tasks', 'run', 'udac_example_dag', 'Run_data_quality_checks', 'scheduled__2022-03-18T06:00:00+00:00', '--job-id', '189', '--raw', '--subdir', 'DAGS_FOLDER/udac_example_dag.py', '--cfg-path', '/var/folders/lh/ngst1lt51m9_gyz7qrg2f3nh0000gn/T/tmpu70n_qrj', '--error-file', '/var/folders/lh/ngst1lt51m9_gyz7qrg2f3nh0000gn/T/tmpt8_yqkck']
[2022-03-18 15:52:19,082] {standard_task_runner.py:77} INFO - Job 189: Subtask Run_data_quality_checks
[2022-03-18 15:52:19,137] {logging_mixin.py:109} INFO - Running <TaskInstance: udac_example_dag.Run_data_quality_checks scheduled__2022-03-18T06:00:00+00:00 [running]> on host 1.0.0.127.in-addr.arpa
[2022-03-18 15:52:19,185] {taskinstance.py:1429} INFO - Exporting the following env vars:
AIRFLOW_CTX_DAG_OWNER=udacity
AIRFLOW_CTX_DAG_ID=udac_example_dag
AIRFLOW_CTX_TASK_ID=Run_data_quality_checks
AIRFLOW_CTX_EXECUTION_DATE=2022-03-18T06:00:00+00:00
AIRFLOW_CTX_DAG_RUN_ID=scheduled__2022-03-18T06:00:00+00:00
[2022-03-18 15:52:19,186] {data_quality.py:52} INFO - Starting to access Redshift
[2022-03-18 15:52:19,186] {data_quality.py:55} INFO - Starting to data quality check
[2022-03-18 15:52:19,187] {connection.py:404} ERROR - Unable to retrieve connection from secrets backend (EnvironmentVariablesBackend). Checking subsequent secrets backend.
Traceback (most recent call last):
  File "/usr/local/anaconda3/envs/airflow_project/lib/python3.9/site-packages/airflow/models/connection.py", line 400, in get_connection_from_secrets
    conn = secrets_backend.get_connection(conn_id=conn_id)
  File "/usr/local/anaconda3/envs/airflow_project/lib/python3.9/site-packages/airflow/secrets/base_secrets.py", line 64, in get_connection
    conn_uri = self.get_conn_uri(conn_id=conn_id)
  File "/usr/local/anaconda3/envs/airflow_project/lib/python3.9/site-packages/airflow/secrets/environment_variables.py", line 33, in get_conn_uri
    environment_uri = os.environ.get(CONN_ENV_PREFIX + conn_id.upper())
AttributeError: 'tuple' object has no attribute 'upper'
[2022-03-18 15:52:19,197] {base.py:70} INFO - Using connection to: id: redshift. Host: redshift-cluster-1.cvmsgkpkbsh2.us-west-2.redshift.amazonaws.com, Port: 5439, Schema: dev, Login: awsuser, Password: ***, extra: {}
[2022-03-18 15:52:22,072] {logging_mixin.py:109} INFO - This is query output: [(6820,)]
[2022-03-18 15:52:22,072] {data_quality.py:73} INFO - What's the table_record ? [(6820,)]
[2022-03-18 15:52:22,072] {connection.py:404} ERROR - Unable to retrieve connection from secrets backend (EnvironmentVariablesBackend). Checking subsequent secrets backend.
Traceback (most recent call last):
  File "/usr/local/anaconda3/envs/airflow_project/lib/python3.9/site-packages/airflow/models/connection.py", line 400, in get_connection_from_secrets
    conn = secrets_backend.get_connection(conn_id=conn_id)
  File "/usr/local/anaconda3/envs/airflow_project/lib/python3.9/site-packages/airflow/secrets/base_secrets.py", line 64, in get_connection
    conn_uri = self.get_conn_uri(conn_id=conn_id)
  File "/usr/local/anaconda3/envs/airflow_project/lib/python3.9/site-packages/airflow/secrets/environment_variables.py", line 33, in get_conn_uri
    environment_uri = os.environ.get(CONN_ENV_PREFIX + conn_id.upper())
AttributeError: 'tuple' object has no attribute 'upper'
[2022-03-18 15:52:22,079] {base.py:70} INFO - Using connection to: id: redshift. Host: redshift-cluster-1.cvmsgkpkbsh2.us-west-2.redshift.amazonaws.com, Port: 5439, Schema: dev, Login: awsuser, Password: ***, extra: {}
[2022-03-18 15:52:24,594] {logging_mixin.py:109} INFO - This is query output: [(14896,)]
[2022-03-18 15:52:24,594] {data_quality.py:73} INFO - What's the table_record ? [(14896,)]
[2022-03-18 15:52:24,595] {connection.py:404} ERROR - Unable to retrieve connection from secrets backend (EnvironmentVariablesBackend). Checking subsequent secrets backend.
Traceback (most recent call last):
  File "/usr/local/anaconda3/envs/airflow_project/lib/python3.9/site-packages/airflow/models/connection.py", line 400, in get_connection_from_secrets
    conn = secrets_backend.get_connection(conn_id=conn_id)
  File "/usr/local/anaconda3/envs/airflow_project/lib/python3.9/site-packages/airflow/secrets/base_secrets.py", line 64, in get_connection
    conn_uri = self.get_conn_uri(conn_id=conn_id)
  File "/usr/local/anaconda3/envs/airflow_project/lib/python3.9/site-packages/airflow/secrets/environment_variables.py", line 33, in get_conn_uri
    environment_uri = os.environ.get(CONN_ENV_PREFIX + conn_id.upper())
AttributeError: 'tuple' object has no attribute 'upper'
[2022-03-18 15:52:24,603] {base.py:70} INFO - Using connection to: id: redshift. Host: redshift-cluster-1.cvmsgkpkbsh2.us-west-2.redshift.amazonaws.com, Port: 5439, Schema: dev, Login: awsuser, Password: ***, extra: {}
[2022-03-18 15:52:27,232] {logging_mixin.py:109} INFO - This is query output: [(104,)]
[2022-03-18 15:52:27,233] {data_quality.py:73} INFO - What's the table_record ? [(104,)]
[2022-03-18 15:52:27,233] {connection.py:404} ERROR - Unable to retrieve connection from secrets backend (EnvironmentVariablesBackend). Checking subsequent secrets backend.
Traceback (most recent call last):
  File "/usr/local/anaconda3/envs/airflow_project/lib/python3.9/site-packages/airflow/models/connection.py", line 400, in get_connection_from_secrets
    conn = secrets_backend.get_connection(conn_id=conn_id)
  File "/usr/local/anaconda3/envs/airflow_project/lib/python3.9/site-packages/airflow/secrets/base_secrets.py", line 64, in get_connection
    conn_uri = self.get_conn_uri(conn_id=conn_id)
  File "/usr/local/anaconda3/envs/airflow_project/lib/python3.9/site-packages/airflow/secrets/environment_variables.py", line 33, in get_conn_uri
    environment_uri = os.environ.get(CONN_ENV_PREFIX + conn_id.upper())
AttributeError: 'tuple' object has no attribute 'upper'
[2022-03-18 15:52:27,241] {base.py:70} INFO - Using connection to: id: redshift. Host: redshift-cluster-1.cvmsgkpkbsh2.us-west-2.redshift.amazonaws.com, Port: 5439, Schema: dev, Login: awsuser, Password: ***, extra: {}
[2022-03-18 15:52:29,793] {logging_mixin.py:109} INFO - This is query output: [(10025,)]
[2022-03-18 15:52:29,793] {data_quality.py:73} INFO - What's the table_record ? [(10025,)]
[2022-03-18 15:52:29,793] {connection.py:404} ERROR - Unable to retrieve connection from secrets backend (EnvironmentVariablesBackend). Checking subsequent secrets backend.
Traceback (most recent call last):
  File "/usr/local/anaconda3/envs/airflow_project/lib/python3.9/site-packages/airflow/models/connection.py", line 400, in get_connection_from_secrets
    conn = secrets_backend.get_connection(conn_id=conn_id)
  File "/usr/local/anaconda3/envs/airflow_project/lib/python3.9/site-packages/airflow/secrets/base_secrets.py", line 64, in get_connection
    conn_uri = self.get_conn_uri(conn_id=conn_id)
  File "/usr/local/anaconda3/envs/airflow_project/lib/python3.9/site-packages/airflow/secrets/environment_variables.py", line 33, in get_conn_uri
    environment_uri = os.environ.get(CONN_ENV_PREFIX + conn_id.upper())
AttributeError: 'tuple' object has no attribute 'upper'
[2022-03-18 15:52:29,801] {base.py:70} INFO - Using connection to: id: redshift. Host: redshift-cluster-1.cvmsgkpkbsh2.us-west-2.redshift.amazonaws.com, Port: 5439, Schema: dev, Login: awsuser, Password: ***, extra: {}
[2022-03-18 15:52:32,352] {logging_mixin.py:109} INFO - This is query output: [(6820,)]
[2022-03-18 15:52:32,353] {data_quality.py:73} INFO - What's the table_record ? [(6820,)]
[2022-03-18 15:52:32,353] {data_quality.py:83} INFO - Check data quality: [{'query': 'SELECT count(*) FROM songplays', 'expected_result': '[(6820,)]'}, {'query': 'SELECT count(*) FROM songs', 'expected_result': '[(14896,)]'}, {'query': 'SELECT count(*) FROM users', 'expected_result': '[(104,)]'}, {'query': 'SELECT count(*) FROM artists', 'expected_result': '[(10025,)]'}, {'query': 'SELECT count(*) FROM time', 'expected_result': '[(6820,)]'}]
[2022-03-18 15:52:32,365] {taskinstance.py:1272} INFO - Marking task as SUCCESS. dag_id=udac_example_dag, task_id=Run_data_quality_checks, execution_date=20220318T060000, start_date=20220318T075219, end_date=20220318T075232
[2022-03-18 15:52:32,381] {local_task_job.py:154} INFO - Task exited with return code 0
[2022-03-18 15:52:32,411] {local_task_job.py:264} INFO - 1 downstream tasks scheduled from follow-on schedule check
