[2022-03-17 13:49:30,816] {taskinstance.py:1037} INFO - Dependencies all met for <TaskInstance: udac_example_dag.load_songplays_fact_table manual__2022-03-17T05:30:10.336355+00:00 [queued]>
[2022-03-17 13:49:30,824] {taskinstance.py:1037} INFO - Dependencies all met for <TaskInstance: udac_example_dag.load_songplays_fact_table manual__2022-03-17T05:30:10.336355+00:00 [queued]>
[2022-03-17 13:49:30,824] {taskinstance.py:1243} INFO - 
--------------------------------------------------------------------------------
[2022-03-17 13:49:30,824] {taskinstance.py:1244} INFO - Starting attempt 3 of 3
[2022-03-17 13:49:30,824] {taskinstance.py:1245} INFO - 
--------------------------------------------------------------------------------
[2022-03-17 13:49:30,836] {taskinstance.py:1264} INFO - Executing <Task(LoadFactOperator): load_songplays_fact_table> on 2022-03-17 05:30:10.336355+00:00
[2022-03-17 13:49:30,838] {standard_task_runner.py:52} INFO - Started process 4864 to run task
[2022-03-17 13:49:30,844] {standard_task_runner.py:76} INFO - Running: ['***', 'tasks', 'run', 'udac_example_dag', 'load_songplays_fact_table', 'manual__2022-03-17T05:30:10.336355+00:00', '--job-id', '20', '--raw', '--subdir', 'DAGS_FOLDER/udac_example_dag.py', '--cfg-path', '/var/folders/lh/ngst1lt51m9_gyz7qrg2f3nh0000gn/T/tmpg0x5loz6', '--error-file', '/var/folders/lh/ngst1lt51m9_gyz7qrg2f3nh0000gn/T/tmpq67b0o40']
[2022-03-17 13:49:30,846] {standard_task_runner.py:77} INFO - Job 20: Subtask load_songplays_fact_table
[2022-03-17 13:49:30,915] {logging_mixin.py:109} INFO - Running <TaskInstance: udac_example_dag.load_songplays_fact_table manual__2022-03-17T05:30:10.336355+00:00 [running]> on host 1.0.0.127.in-addr.arpa
[2022-03-17 13:49:30,969] {taskinstance.py:1429} INFO - Exporting the following env vars:
AIRFLOW_CTX_DAG_OWNER=udacity
AIRFLOW_CTX_DAG_ID=udac_example_dag
AIRFLOW_CTX_TASK_ID=load_songplays_fact_table
AIRFLOW_CTX_EXECUTION_DATE=2022-03-17T05:30:10.336355+00:00
AIRFLOW_CTX_DAG_RUN_ID=manual__2022-03-17T05:30:10.336355+00:00
[2022-03-17 13:49:30,969] {taskinstance.py:1718} ERROR - Task failed with exception
Traceback (most recent call last):
  File "/usr/local/anaconda3/envs/data_pipeline/lib/python3.8/site-packages/airflow/models/taskinstance.py", line 1334, in _run_raw_task
    self._execute_task_with_callbacks(context)
  File "/usr/local/anaconda3/envs/data_pipeline/lib/python3.8/site-packages/airflow/models/taskinstance.py", line 1460, in _execute_task_with_callbacks
    result = self._execute_task(context, self.task)
  File "/usr/local/anaconda3/envs/data_pipeline/lib/python3.8/site-packages/airflow/models/taskinstance.py", line 1516, in _execute_task
    result = execute_callable(context=context)
  File "/Users/oneforall_nick/workspace/airflow/plugins/operators/load_fact.py", line 73, in execute
    self.load_songplays_fact_table(redshift_hook)
TypeError: load_songplays_fact_table() missing 1 required positional argument: 'context'
[2022-03-17 13:49:30,982] {taskinstance.py:1272} INFO - Marking task as FAILED. dag_id=udac_example_dag, task_id=load_songplays_fact_table, execution_date=20220317T053010, start_date=20220317T054930, end_date=20220317T054930
[2022-03-17 13:49:30,990] {standard_task_runner.py:89} ERROR - Failed to execute job 20 for task load_songplays_fact_table
Traceback (most recent call last):
  File "/usr/local/anaconda3/envs/data_pipeline/lib/python3.8/site-packages/airflow/task/task_runner/standard_task_runner.py", line 85, in _start_by_fork
    args.func(args, dag=self.dag)
  File "/usr/local/anaconda3/envs/data_pipeline/lib/python3.8/site-packages/airflow/cli/cli_parser.py", line 48, in command
    return func(*args, **kwargs)
  File "/usr/local/anaconda3/envs/data_pipeline/lib/python3.8/site-packages/airflow/utils/cli.py", line 92, in wrapper
    return f(*args, **kwargs)
  File "/usr/local/anaconda3/envs/data_pipeline/lib/python3.8/site-packages/airflow/cli/commands/task_command.py", line 298, in task_run
    _run_task_by_selected_method(args, dag, ti)
  File "/usr/local/anaconda3/envs/data_pipeline/lib/python3.8/site-packages/airflow/cli/commands/task_command.py", line 107, in _run_task_by_selected_method
    _run_raw_task(args, ti)
  File "/usr/local/anaconda3/envs/data_pipeline/lib/python3.8/site-packages/airflow/cli/commands/task_command.py", line 180, in _run_raw_task
    ti._run_raw_task(
  File "/usr/local/anaconda3/envs/data_pipeline/lib/python3.8/site-packages/airflow/utils/session.py", line 70, in wrapper
    return func(*args, session=session, **kwargs)
  File "/usr/local/anaconda3/envs/data_pipeline/lib/python3.8/site-packages/airflow/models/taskinstance.py", line 1334, in _run_raw_task
    self._execute_task_with_callbacks(context)
  File "/usr/local/anaconda3/envs/data_pipeline/lib/python3.8/site-packages/airflow/models/taskinstance.py", line 1460, in _execute_task_with_callbacks
    result = self._execute_task(context, self.task)
  File "/usr/local/anaconda3/envs/data_pipeline/lib/python3.8/site-packages/airflow/models/taskinstance.py", line 1516, in _execute_task
    result = execute_callable(context=context)
  File "/Users/oneforall_nick/workspace/airflow/plugins/operators/load_fact.py", line 73, in execute
    self.load_songplays_fact_table(redshift_hook)
TypeError: load_songplays_fact_table() missing 1 required positional argument: 'context'
[2022-03-17 13:49:31,018] {local_task_job.py:154} INFO - Task exited with return code 1
[2022-03-17 13:49:31,046] {local_task_job.py:264} INFO - 0 downstream tasks scheduled from follow-on schedule check
