[2022-03-19 22:24:29,640] {taskinstance.py:1037} INFO - Dependencies all met for <TaskInstance: udac_new_v1_dag.Run_data_quality_checks manual__2022-03-19T14:21:18.171413+00:00 [queued]>
[2022-03-19 22:24:29,650] {taskinstance.py:1037} INFO - Dependencies all met for <TaskInstance: udac_new_v1_dag.Run_data_quality_checks manual__2022-03-19T14:21:18.171413+00:00 [queued]>
[2022-03-19 22:24:29,651] {taskinstance.py:1243} INFO - 
--------------------------------------------------------------------------------
[2022-03-19 22:24:29,651] {taskinstance.py:1244} INFO - Starting attempt 1 of 2
[2022-03-19 22:24:29,651] {taskinstance.py:1245} INFO - 
--------------------------------------------------------------------------------
[2022-03-19 22:24:29,658] {taskinstance.py:1264} INFO - Executing <Task(DataQualityOperator): Run_data_quality_checks> on 2022-03-19 14:21:18.171413+00:00
[2022-03-19 22:24:29,661] {standard_task_runner.py:52} INFO - Started process 46571 to run task
[2022-03-19 22:24:29,665] {standard_task_runner.py:76} INFO - Running: ['***', 'tasks', 'run', 'udac_new_v1_dag', 'Run_data_quality_checks', 'manual__2022-03-19T14:21:18.171413+00:00', '--job-id', '107', '--raw', '--subdir', 'DAGS_FOLDER/udac_v1.py', '--cfg-path', '/var/folders/lh/ngst1lt51m9_gyz7qrg2f3nh0000gn/T/tmp5pupggns', '--error-file', '/var/folders/lh/ngst1lt51m9_gyz7qrg2f3nh0000gn/T/tmp106_yt_v']
[2022-03-19 22:24:29,667] {standard_task_runner.py:77} INFO - Job 107: Subtask Run_data_quality_checks
[2022-03-19 22:24:29,722] {logging_mixin.py:109} INFO - Running <TaskInstance: udac_new_v1_dag.Run_data_quality_checks manual__2022-03-19T14:21:18.171413+00:00 [running]> on host 1.0.0.127.in-addr.arpa
[2022-03-19 22:24:29,770] {taskinstance.py:1429} INFO - Exporting the following env vars:
AIRFLOW_CTX_DAG_OWNER=udacity
AIRFLOW_CTX_DAG_ID=udac_new_v1_dag
AIRFLOW_CTX_TASK_ID=Run_data_quality_checks
AIRFLOW_CTX_EXECUTION_DATE=2022-03-19T14:21:18.171413+00:00
AIRFLOW_CTX_DAG_RUN_ID=manual__2022-03-19T14:21:18.171413+00:00
[2022-03-19 22:24:29,771] {data_quality.py:55} INFO - Starting to access Redshift
[2022-03-19 22:24:29,771] {data_quality.py:58} INFO - Starting to data quality check
[2022-03-19 22:24:29,771] {taskinstance.py:1718} ERROR - Task failed with exception
Traceback (most recent call last):
  File "/usr/local/anaconda3/envs/airflow_project/lib/python3.9/site-packages/airflow/models/taskinstance.py", line 1334, in _run_raw_task
    self._execute_task_with_callbacks(context)
  File "/usr/local/anaconda3/envs/airflow_project/lib/python3.9/site-packages/airflow/models/taskinstance.py", line 1460, in _execute_task_with_callbacks
    result = self._execute_task(context, self.task)
  File "/usr/local/anaconda3/envs/airflow_project/lib/python3.9/site-packages/airflow/models/taskinstance.py", line 1516, in _execute_task
    result = execute_callable(context=context)
  File "/Users/oneforall_nick/workspace/airflow/plugins/operators/data_quality.py", line 59, in execute
    self.data_quality_check(redshift_hook)
  File "/Users/oneforall_nick/workspace/airflow/plugins/operators/data_quality.py", line 78, in data_quality_check
    for fact_table in self.table_name[0]["fact_table"]:
KeyError: 0
[2022-03-19 22:24:29,785] {taskinstance.py:1272} INFO - Marking task as UP_FOR_RETRY. dag_id=udac_new_v1_dag, task_id=Run_data_quality_checks, execution_date=20220319T142118, start_date=20220319T142429, end_date=20220319T142429
[2022-03-19 22:24:29,796] {standard_task_runner.py:89} ERROR - Failed to execute job 107 for task Run_data_quality_checks
Traceback (most recent call last):
  File "/usr/local/anaconda3/envs/airflow_project/lib/python3.9/site-packages/airflow/task/task_runner/standard_task_runner.py", line 85, in _start_by_fork
    args.func(args, dag=self.dag)
  File "/usr/local/anaconda3/envs/airflow_project/lib/python3.9/site-packages/airflow/cli/cli_parser.py", line 48, in command
    return func(*args, **kwargs)
  File "/usr/local/anaconda3/envs/airflow_project/lib/python3.9/site-packages/airflow/utils/cli.py", line 92, in wrapper
    return f(*args, **kwargs)
  File "/usr/local/anaconda3/envs/airflow_project/lib/python3.9/site-packages/airflow/cli/commands/task_command.py", line 298, in task_run
    _run_task_by_selected_method(args, dag, ti)
  File "/usr/local/anaconda3/envs/airflow_project/lib/python3.9/site-packages/airflow/cli/commands/task_command.py", line 107, in _run_task_by_selected_method
    _run_raw_task(args, ti)
  File "/usr/local/anaconda3/envs/airflow_project/lib/python3.9/site-packages/airflow/cli/commands/task_command.py", line 180, in _run_raw_task
    ti._run_raw_task(
  File "/usr/local/anaconda3/envs/airflow_project/lib/python3.9/site-packages/airflow/utils/session.py", line 70, in wrapper
    return func(*args, session=session, **kwargs)
  File "/usr/local/anaconda3/envs/airflow_project/lib/python3.9/site-packages/airflow/models/taskinstance.py", line 1334, in _run_raw_task
    self._execute_task_with_callbacks(context)
  File "/usr/local/anaconda3/envs/airflow_project/lib/python3.9/site-packages/airflow/models/taskinstance.py", line 1460, in _execute_task_with_callbacks
    result = self._execute_task(context, self.task)
  File "/usr/local/anaconda3/envs/airflow_project/lib/python3.9/site-packages/airflow/models/taskinstance.py", line 1516, in _execute_task
    result = execute_callable(context=context)
  File "/Users/oneforall_nick/workspace/airflow/plugins/operators/data_quality.py", line 59, in execute
    self.data_quality_check(redshift_hook)
  File "/Users/oneforall_nick/workspace/airflow/plugins/operators/data_quality.py", line 78, in data_quality_check
    for fact_table in self.table_name[0]["fact_table"]:
KeyError: 0
[2022-03-19 22:24:29,843] {local_task_job.py:154} INFO - Task exited with return code 1
[2022-03-19 22:24:29,876] {local_task_job.py:264} INFO - 0 downstream tasks scheduled from follow-on schedule check
