[2022-03-17 15:56:32,255] {taskinstance.py:1037} INFO - Dependencies all met for <TaskInstance: udac_example_dag.Run_data_quality_checks manual__2022-03-17T07:56:09.695259+00:00 [queued]>
[2022-03-17 15:56:32,265] {taskinstance.py:1037} INFO - Dependencies all met for <TaskInstance: udac_example_dag.Run_data_quality_checks manual__2022-03-17T07:56:09.695259+00:00 [queued]>
[2022-03-17 15:56:32,266] {taskinstance.py:1243} INFO - 
--------------------------------------------------------------------------------
[2022-03-17 15:56:32,266] {taskinstance.py:1244} INFO - Starting attempt 1 of 3
[2022-03-17 15:56:32,266] {taskinstance.py:1245} INFO - 
--------------------------------------------------------------------------------
[2022-03-17 15:56:32,274] {taskinstance.py:1264} INFO - Executing <Task(DataQualityOperator): Run_data_quality_checks> on 2022-03-17 07:56:09.695259+00:00
[2022-03-17 15:56:32,277] {standard_task_runner.py:52} INFO - Started process 66363 to run task
[2022-03-17 15:56:32,281] {standard_task_runner.py:76} INFO - Running: ['***', 'tasks', 'run', 'udac_example_dag', 'Run_data_quality_checks', 'manual__2022-03-17T07:56:09.695259+00:00', '--job-id', '95', '--raw', '--subdir', 'DAGS_FOLDER/udac_example_dag.py', '--cfg-path', '/var/folders/lh/ngst1lt51m9_gyz7qrg2f3nh0000gn/T/tmp2a2kiyn8', '--error-file', '/var/folders/lh/ngst1lt51m9_gyz7qrg2f3nh0000gn/T/tmpidsgow3j']
[2022-03-17 15:56:32,283] {standard_task_runner.py:77} INFO - Job 95: Subtask Run_data_quality_checks
[2022-03-17 15:56:32,339] {logging_mixin.py:109} INFO - Running <TaskInstance: udac_example_dag.Run_data_quality_checks manual__2022-03-17T07:56:09.695259+00:00 [running]> on host OneForAll-NickdeMacBook-Pro.local
[2022-03-17 15:56:32,401] {taskinstance.py:1429} INFO - Exporting the following env vars:
AIRFLOW_CTX_DAG_OWNER=udacity
AIRFLOW_CTX_DAG_ID=udac_example_dag
AIRFLOW_CTX_TASK_ID=Run_data_quality_checks
AIRFLOW_CTX_EXECUTION_DATE=2022-03-17T07:56:09.695259+00:00
AIRFLOW_CTX_DAG_RUN_ID=manual__2022-03-17T07:56:09.695259+00:00
[2022-03-17 15:56:32,402] {data_quality.py:46} INFO - Starting to access Redshift
[2022-03-17 15:56:32,402] {data_quality.py:49} INFO - Starting to data quality check
[2022-03-17 15:56:32,403] {taskinstance.py:1718} ERROR - Task failed with exception
Traceback (most recent call last):
  File "/usr/local/anaconda3/envs/data_pipeline/lib/python3.8/site-packages/airflow/models/taskinstance.py", line 1334, in _run_raw_task
    self._execute_task_with_callbacks(context)
  File "/usr/local/anaconda3/envs/data_pipeline/lib/python3.8/site-packages/airflow/models/taskinstance.py", line 1460, in _execute_task_with_callbacks
    result = self._execute_task(context, self.task)
  File "/usr/local/anaconda3/envs/data_pipeline/lib/python3.8/site-packages/airflow/models/taskinstance.py", line 1516, in _execute_task
    result = execute_callable(context=context)
  File "/Users/oneforall_nick/workspace/airflow/plugins/operators/data_quality.py", line 50, in execute
    self.data_quality_check(redshift_hook, context)
  File "/Users/oneforall_nick/workspace/airflow/plugins/operators/data_quality.py", line 60, in data_quality_check
    table_data_check_render = self.table_name.format(**context)
AttributeError: 'tuple' object has no attribute 'format'
[2022-03-17 15:56:32,415] {taskinstance.py:1272} INFO - Marking task as UP_FOR_RETRY. dag_id=udac_example_dag, task_id=Run_data_quality_checks, execution_date=20220317T075609, start_date=20220317T075632, end_date=20220317T075632
[2022-03-17 15:56:32,424] {standard_task_runner.py:89} ERROR - Failed to execute job 95 for task Run_data_quality_checks
Traceback (most recent call last):
  File "/usr/local/anaconda3/envs/data_pipeline/lib/python3.8/site-packages/airflow/task/task_runner/standard_task_runner.py", line 85, in _start_by_fork
    args.func(args, dag=self.dag)
  File "/usr/local/anaconda3/envs/data_pipeline/lib/python3.8/site-packages/airflow/cli/cli_parser.py", line 48, in command
    return func(*args, **kwargs)
  File "/usr/local/anaconda3/envs/data_pipeline/lib/python3.8/site-packages/airflow/utils/cli.py", line 92, in wrapper
    return f(*args, **kwargs)
  File "/usr/local/anaconda3/envs/data_pipeline/lib/python3.8/site-packages/airflow/cli/commands/task_command.py", line 298, in task_run
    _run_task_by_selected_method(args, dag, ti)
  File "/usr/local/anaconda3/envs/data_pipeline/lib/python3.8/site-packages/airflow/cli/commands/task_command.py", line 107, in _run_task_by_selected_method
    _run_raw_task(args, ti)
  File "/usr/local/anaconda3/envs/data_pipeline/lib/python3.8/site-packages/airflow/cli/commands/task_command.py", line 180, in _run_raw_task
    ti._run_raw_task(
  File "/usr/local/anaconda3/envs/data_pipeline/lib/python3.8/site-packages/airflow/utils/session.py", line 70, in wrapper
    return func(*args, session=session, **kwargs)
  File "/usr/local/anaconda3/envs/data_pipeline/lib/python3.8/site-packages/airflow/models/taskinstance.py", line 1334, in _run_raw_task
    self._execute_task_with_callbacks(context)
  File "/usr/local/anaconda3/envs/data_pipeline/lib/python3.8/site-packages/airflow/models/taskinstance.py", line 1460, in _execute_task_with_callbacks
    result = self._execute_task(context, self.task)
  File "/usr/local/anaconda3/envs/data_pipeline/lib/python3.8/site-packages/airflow/models/taskinstance.py", line 1516, in _execute_task
    result = execute_callable(context=context)
  File "/Users/oneforall_nick/workspace/airflow/plugins/operators/data_quality.py", line 50, in execute
    self.data_quality_check(redshift_hook, context)
  File "/Users/oneforall_nick/workspace/airflow/plugins/operators/data_quality.py", line 60, in data_quality_check
    table_data_check_render = self.table_name.format(**context)
AttributeError: 'tuple' object has no attribute 'format'
[2022-03-17 15:56:32,457] {local_task_job.py:154} INFO - Task exited with return code 1
[2022-03-17 15:56:32,489] {local_task_job.py:264} INFO - 0 downstream tasks scheduled from follow-on schedule check
