[2022-03-19 22:19:08,172] {taskinstance.py:1037} INFO - Dependencies all met for <TaskInstance: udac_new_v1_dag.Run_data_quality_checks manual__2022-03-19T14:16:00.007102+00:00 [queued]>
[2022-03-19 22:19:08,184] {taskinstance.py:1037} INFO - Dependencies all met for <TaskInstance: udac_new_v1_dag.Run_data_quality_checks manual__2022-03-19T14:16:00.007102+00:00 [queued]>
[2022-03-19 22:19:08,184] {taskinstance.py:1243} INFO - 
--------------------------------------------------------------------------------
[2022-03-19 22:19:08,185] {taskinstance.py:1244} INFO - Starting attempt 1 of 2
[2022-03-19 22:19:08,185] {taskinstance.py:1245} INFO - 
--------------------------------------------------------------------------------
[2022-03-19 22:19:08,194] {taskinstance.py:1264} INFO - Executing <Task(DataQualityOperator): Run_data_quality_checks> on 2022-03-19 14:16:00.007102+00:00
[2022-03-19 22:19:08,197] {standard_task_runner.py:52} INFO - Started process 45591 to run task
[2022-03-19 22:19:08,202] {standard_task_runner.py:76} INFO - Running: ['***', 'tasks', 'run', 'udac_new_v1_dag', 'Run_data_quality_checks', 'manual__2022-03-19T14:16:00.007102+00:00', '--job-id', '99', '--raw', '--subdir', 'DAGS_FOLDER/udac_v1.py', '--cfg-path', '/var/folders/lh/ngst1lt51m9_gyz7qrg2f3nh0000gn/T/tmpp93e92tx', '--error-file', '/var/folders/lh/ngst1lt51m9_gyz7qrg2f3nh0000gn/T/tmplxpievvj']
[2022-03-19 22:19:08,205] {standard_task_runner.py:77} INFO - Job 99: Subtask Run_data_quality_checks
[2022-03-19 22:19:08,276] {logging_mixin.py:109} INFO - Running <TaskInstance: udac_new_v1_dag.Run_data_quality_checks manual__2022-03-19T14:16:00.007102+00:00 [running]> on host 1.0.0.127.in-addr.arpa
[2022-03-19 22:19:08,339] {taskinstance.py:1429} INFO - Exporting the following env vars:
AIRFLOW_CTX_DAG_OWNER=udacity
AIRFLOW_CTX_DAG_ID=udac_new_v1_dag
AIRFLOW_CTX_TASK_ID=Run_data_quality_checks
AIRFLOW_CTX_EXECUTION_DATE=2022-03-19T14:16:00.007102+00:00
AIRFLOW_CTX_DAG_RUN_ID=manual__2022-03-19T14:16:00.007102+00:00
[2022-03-19 22:19:08,340] {data_quality.py:55} INFO - Starting to access Redshift
[2022-03-19 22:19:08,340] {data_quality.py:58} INFO - Starting to data quality check
[2022-03-19 22:19:08,340] {connection.py:404} ERROR - Unable to retrieve connection from secrets backend (EnvironmentVariablesBackend). Checking subsequent secrets backend.
Traceback (most recent call last):
  File "/usr/local/anaconda3/envs/airflow_project/lib/python3.9/site-packages/airflow/models/connection.py", line 400, in get_connection_from_secrets
    conn = secrets_backend.get_connection(conn_id=conn_id)
  File "/usr/local/anaconda3/envs/airflow_project/lib/python3.9/site-packages/airflow/secrets/base_secrets.py", line 64, in get_connection
    conn_uri = self.get_conn_uri(conn_id=conn_id)
  File "/usr/local/anaconda3/envs/airflow_project/lib/python3.9/site-packages/airflow/secrets/environment_variables.py", line 33, in get_conn_uri
    environment_uri = os.environ.get(CONN_ENV_PREFIX + conn_id.upper())
AttributeError: 'tuple' object has no attribute 'upper'
[2022-03-19 22:19:08,352] {base.py:70} INFO - Using connection to: id: redshift. Host: redshift-cluster-1.cvmsgkpkbsh2.us-west-2.redshift.amazonaws.com, Port: 5439, Schema: dev, Login: awsuser, Password: ***, extra: {}
[2022-03-19 22:19:09,733] {connection.py:404} ERROR - Unable to retrieve connection from secrets backend (EnvironmentVariablesBackend). Checking subsequent secrets backend.
Traceback (most recent call last):
  File "/usr/local/anaconda3/envs/airflow_project/lib/python3.9/site-packages/airflow/models/connection.py", line 400, in get_connection_from_secrets
    conn = secrets_backend.get_connection(conn_id=conn_id)
  File "/usr/local/anaconda3/envs/airflow_project/lib/python3.9/site-packages/airflow/secrets/base_secrets.py", line 64, in get_connection
    conn_uri = self.get_conn_uri(conn_id=conn_id)
  File "/usr/local/anaconda3/envs/airflow_project/lib/python3.9/site-packages/airflow/secrets/environment_variables.py", line 33, in get_conn_uri
    environment_uri = os.environ.get(CONN_ENV_PREFIX + conn_id.upper())
AttributeError: 'tuple' object has no attribute 'upper'
[2022-03-19 22:19:09,740] {base.py:70} INFO - Using connection to: id: redshift. Host: redshift-cluster-1.cvmsgkpkbsh2.us-west-2.redshift.amazonaws.com, Port: 5439, Schema: dev, Login: awsuser, Password: ***, extra: {}
[2022-03-19 22:19:11,107] {connection.py:404} ERROR - Unable to retrieve connection from secrets backend (EnvironmentVariablesBackend). Checking subsequent secrets backend.
Traceback (most recent call last):
  File "/usr/local/anaconda3/envs/airflow_project/lib/python3.9/site-packages/airflow/models/connection.py", line 400, in get_connection_from_secrets
    conn = secrets_backend.get_connection(conn_id=conn_id)
  File "/usr/local/anaconda3/envs/airflow_project/lib/python3.9/site-packages/airflow/secrets/base_secrets.py", line 64, in get_connection
    conn_uri = self.get_conn_uri(conn_id=conn_id)
  File "/usr/local/anaconda3/envs/airflow_project/lib/python3.9/site-packages/airflow/secrets/environment_variables.py", line 33, in get_conn_uri
    environment_uri = os.environ.get(CONN_ENV_PREFIX + conn_id.upper())
AttributeError: 'tuple' object has no attribute 'upper'
[2022-03-19 22:19:11,113] {base.py:70} INFO - Using connection to: id: redshift. Host: redshift-cluster-1.cvmsgkpkbsh2.us-west-2.redshift.amazonaws.com, Port: 5439, Schema: dev, Login: awsuser, Password: ***, extra: {}
[2022-03-19 22:19:12,477] {connection.py:404} ERROR - Unable to retrieve connection from secrets backend (EnvironmentVariablesBackend). Checking subsequent secrets backend.
Traceback (most recent call last):
  File "/usr/local/anaconda3/envs/airflow_project/lib/python3.9/site-packages/airflow/models/connection.py", line 400, in get_connection_from_secrets
    conn = secrets_backend.get_connection(conn_id=conn_id)
  File "/usr/local/anaconda3/envs/airflow_project/lib/python3.9/site-packages/airflow/secrets/base_secrets.py", line 64, in get_connection
    conn_uri = self.get_conn_uri(conn_id=conn_id)
  File "/usr/local/anaconda3/envs/airflow_project/lib/python3.9/site-packages/airflow/secrets/environment_variables.py", line 33, in get_conn_uri
    environment_uri = os.environ.get(CONN_ENV_PREFIX + conn_id.upper())
AttributeError: 'tuple' object has no attribute 'upper'
[2022-03-19 22:19:12,485] {base.py:70} INFO - Using connection to: id: redshift. Host: redshift-cluster-1.cvmsgkpkbsh2.us-west-2.redshift.amazonaws.com, Port: 5439, Schema: dev, Login: awsuser, Password: ***, extra: {}
[2022-03-19 22:19:13,850] {connection.py:404} ERROR - Unable to retrieve connection from secrets backend (EnvironmentVariablesBackend). Checking subsequent secrets backend.
Traceback (most recent call last):
  File "/usr/local/anaconda3/envs/airflow_project/lib/python3.9/site-packages/airflow/models/connection.py", line 400, in get_connection_from_secrets
    conn = secrets_backend.get_connection(conn_id=conn_id)
  File "/usr/local/anaconda3/envs/airflow_project/lib/python3.9/site-packages/airflow/secrets/base_secrets.py", line 64, in get_connection
    conn_uri = self.get_conn_uri(conn_id=conn_id)
  File "/usr/local/anaconda3/envs/airflow_project/lib/python3.9/site-packages/airflow/secrets/environment_variables.py", line 33, in get_conn_uri
    environment_uri = os.environ.get(CONN_ENV_PREFIX + conn_id.upper())
AttributeError: 'tuple' object has no attribute 'upper'
[2022-03-19 22:19:13,860] {base.py:70} INFO - Using connection to: id: redshift. Host: redshift-cluster-1.cvmsgkpkbsh2.us-west-2.redshift.amazonaws.com, Port: 5439, Schema: dev, Login: awsuser, Password: ***, extra: {}
[2022-03-19 22:19:15,241] {taskinstance.py:1272} INFO - Marking task as SUCCESS. dag_id=udac_new_v1_dag, task_id=Run_data_quality_checks, execution_date=20220319T141600, start_date=20220319T141908, end_date=20220319T141915
[2022-03-19 22:19:15,275] {local_task_job.py:154} INFO - Task exited with return code 0
[2022-03-19 22:19:15,309] {local_task_job.py:264} INFO - 1 downstream tasks scheduled from follow-on schedule check
