[2022-03-19 22:43:00,886] {taskinstance.py:1037} INFO - Dependencies all met for <TaskInstance: udac_new_v1_dag.Run_data_quality_checks manual__2022-03-19T14:39:54.561236+00:00 [queued]>
[2022-03-19 22:43:00,896] {taskinstance.py:1037} INFO - Dependencies all met for <TaskInstance: udac_new_v1_dag.Run_data_quality_checks manual__2022-03-19T14:39:54.561236+00:00 [queued]>
[2022-03-19 22:43:00,896] {taskinstance.py:1243} INFO - 
--------------------------------------------------------------------------------
[2022-03-19 22:43:00,896] {taskinstance.py:1244} INFO - Starting attempt 1 of 2
[2022-03-19 22:43:00,897] {taskinstance.py:1245} INFO - 
--------------------------------------------------------------------------------
[2022-03-19 22:43:00,906] {taskinstance.py:1264} INFO - Executing <Task(DataQualityOperator): Run_data_quality_checks> on 2022-03-19 14:39:54.561236+00:00
[2022-03-19 22:43:00,909] {standard_task_runner.py:52} INFO - Started process 49014 to run task
[2022-03-19 22:43:00,913] {standard_task_runner.py:76} INFO - Running: ['***', 'tasks', 'run', 'udac_new_v1_dag', 'Run_data_quality_checks', 'manual__2022-03-19T14:39:54.561236+00:00', '--job-id', '116', '--raw', '--subdir', 'DAGS_FOLDER/udac_v1.py', '--cfg-path', '/var/folders/lh/ngst1lt51m9_gyz7qrg2f3nh0000gn/T/tmpwhhwrqqk', '--error-file', '/var/folders/lh/ngst1lt51m9_gyz7qrg2f3nh0000gn/T/tmpktyom2rc']
[2022-03-19 22:43:00,915] {standard_task_runner.py:77} INFO - Job 116: Subtask Run_data_quality_checks
[2022-03-19 22:43:00,971] {logging_mixin.py:109} INFO - Running <TaskInstance: udac_new_v1_dag.Run_data_quality_checks manual__2022-03-19T14:39:54.561236+00:00 [running]> on host 1.0.0.127.in-addr.arpa
[2022-03-19 22:43:01,019] {taskinstance.py:1429} INFO - Exporting the following env vars:
AIRFLOW_CTX_DAG_OWNER=udacity
AIRFLOW_CTX_DAG_ID=udac_new_v1_dag
AIRFLOW_CTX_TASK_ID=Run_data_quality_checks
AIRFLOW_CTX_EXECUTION_DATE=2022-03-19T14:39:54.561236+00:00
AIRFLOW_CTX_DAG_RUN_ID=manual__2022-03-19T14:39:54.561236+00:00
[2022-03-19 22:43:01,019] {data_quality.py:55} INFO - Starting to access Redshift
[2022-03-19 22:43:01,020] {data_quality.py:58} INFO - Starting to data quality check
[2022-03-19 22:43:01,020] {data_quality.py:77} INFO - This is data: {'stage_tables': [{'log_data': 'staging_events', 'song_data': 'staging_songs'}], 'fact_table': [{'table_name': 'songplays', 'columns': ['playid, start_time, userid, level, songid, artistid, sessionid, location, user_agent']}], 'dimension_table': [{'table_name': 'songs', 'columns': ['songid, title, artistid, year, duration']}, {'table_name': 'users', 'columns': ['userid, first_name, last_name, gender, level']}, {'table_name': 'time', 'columns': ['start_time, hour, day, week, month, year, weekday']}, {'table_name': 'artists', 'columns': ['artistid, name, location, lattitude, longitude']}]}
[2022-03-19 22:43:01,020] {data_quality.py:78} INFO - This is data type: <class 'dict'>
[2022-03-19 22:43:01,021] {taskinstance.py:1718} ERROR - Task failed with exception
Traceback (most recent call last):
  File "/usr/local/anaconda3/envs/airflow_project/lib/python3.9/site-packages/airflow/models/taskinstance.py", line 1334, in _run_raw_task
    self._execute_task_with_callbacks(context)
  File "/usr/local/anaconda3/envs/airflow_project/lib/python3.9/site-packages/airflow/models/taskinstance.py", line 1460, in _execute_task_with_callbacks
    result = self._execute_task(context, self.task)
  File "/usr/local/anaconda3/envs/airflow_project/lib/python3.9/site-packages/airflow/models/taskinstance.py", line 1516, in _execute_task
    result = execute_callable(context=context)
  File "/Users/oneforall_nick/workspace/airflow/plugins/operators/data_quality.py", line 59, in execute
    self.data_quality_check(redshift_hook)
  File "/Users/oneforall_nick/workspace/airflow/plugins/operators/data_quality.py", line 81, in data_quality_check
    for fact_table in self.table_name[0]["fact_table"]:
KeyError: 0
[2022-03-19 22:43:01,035] {taskinstance.py:1272} INFO - Marking task as UP_FOR_RETRY. dag_id=udac_new_v1_dag, task_id=Run_data_quality_checks, execution_date=20220319T143954, start_date=20220319T144300, end_date=20220319T144301
[2022-03-19 22:43:01,044] {standard_task_runner.py:89} ERROR - Failed to execute job 116 for task Run_data_quality_checks
Traceback (most recent call last):
  File "/usr/local/anaconda3/envs/airflow_project/lib/python3.9/site-packages/airflow/task/task_runner/standard_task_runner.py", line 85, in _start_by_fork
    args.func(args, dag=self.dag)
  File "/usr/local/anaconda3/envs/airflow_project/lib/python3.9/site-packages/airflow/cli/cli_parser.py", line 48, in command
    return func(*args, **kwargs)
  File "/usr/local/anaconda3/envs/airflow_project/lib/python3.9/site-packages/airflow/utils/cli.py", line 92, in wrapper
    return f(*args, **kwargs)
  File "/usr/local/anaconda3/envs/airflow_project/lib/python3.9/site-packages/airflow/cli/commands/task_command.py", line 298, in task_run
    _run_task_by_selected_method(args, dag, ti)
  File "/usr/local/anaconda3/envs/airflow_project/lib/python3.9/site-packages/airflow/cli/commands/task_command.py", line 107, in _run_task_by_selected_method
    _run_raw_task(args, ti)
  File "/usr/local/anaconda3/envs/airflow_project/lib/python3.9/site-packages/airflow/cli/commands/task_command.py", line 180, in _run_raw_task
    ti._run_raw_task(
  File "/usr/local/anaconda3/envs/airflow_project/lib/python3.9/site-packages/airflow/utils/session.py", line 70, in wrapper
    return func(*args, session=session, **kwargs)
  File "/usr/local/anaconda3/envs/airflow_project/lib/python3.9/site-packages/airflow/models/taskinstance.py", line 1334, in _run_raw_task
    self._execute_task_with_callbacks(context)
  File "/usr/local/anaconda3/envs/airflow_project/lib/python3.9/site-packages/airflow/models/taskinstance.py", line 1460, in _execute_task_with_callbacks
    result = self._execute_task(context, self.task)
  File "/usr/local/anaconda3/envs/airflow_project/lib/python3.9/site-packages/airflow/models/taskinstance.py", line 1516, in _execute_task
    result = execute_callable(context=context)
  File "/Users/oneforall_nick/workspace/airflow/plugins/operators/data_quality.py", line 59, in execute
    self.data_quality_check(redshift_hook)
  File "/Users/oneforall_nick/workspace/airflow/plugins/operators/data_quality.py", line 81, in data_quality_check
    for fact_table in self.table_name[0]["fact_table"]:
KeyError: 0
[2022-03-19 22:43:01,089] {local_task_job.py:154} INFO - Task exited with return code 1
[2022-03-19 22:43:01,132] {local_task_job.py:264} INFO - 0 downstream tasks scheduled from follow-on schedule check
