[2022-03-17 13:39:04,509] {taskinstance.py:1037} INFO - Dependencies all met for <TaskInstance: udac_example_dag.load_songplays_fact_table scheduled__2022-03-17T04:00:00+00:00 [queued]>
[2022-03-17 13:39:04,520] {taskinstance.py:1037} INFO - Dependencies all met for <TaskInstance: udac_example_dag.load_songplays_fact_table scheduled__2022-03-17T04:00:00+00:00 [queued]>
[2022-03-17 13:39:04,520] {taskinstance.py:1243} INFO - 
--------------------------------------------------------------------------------
[2022-03-17 13:39:04,520] {taskinstance.py:1244} INFO - Starting attempt 3 of 3
[2022-03-17 13:39:04,521] {taskinstance.py:1245} INFO - 
--------------------------------------------------------------------------------
[2022-03-17 13:39:04,528] {taskinstance.py:1264} INFO - Executing <Task(LoadFactOperator): load_songplays_fact_table> on 2022-03-17 04:00:00+00:00
[2022-03-17 13:39:04,530] {standard_task_runner.py:52} INFO - Started process 98677 to run task
[2022-03-17 13:39:04,539] {standard_task_runner.py:76} INFO - Running: ['***', 'tasks', 'run', 'udac_example_dag', 'load_songplays_fact_table', 'scheduled__2022-03-17T04:00:00+00:00', '--job-id', '15', '--raw', '--subdir', 'DAGS_FOLDER/udac_example_dag.py', '--cfg-path', '/var/folders/lh/ngst1lt51m9_gyz7qrg2f3nh0000gn/T/tmph7ut91oy', '--error-file', '/var/folders/lh/ngst1lt51m9_gyz7qrg2f3nh0000gn/T/tmpw46w1z28']
[2022-03-17 13:39:04,541] {standard_task_runner.py:77} INFO - Job 15: Subtask load_songplays_fact_table
[2022-03-17 13:39:04,605] {logging_mixin.py:109} INFO - Running <TaskInstance: udac_example_dag.load_songplays_fact_table scheduled__2022-03-17T04:00:00+00:00 [running]> on host 1.0.0.127.in-addr.arpa
[2022-03-17 13:39:04,652] {taskinstance.py:1429} INFO - Exporting the following env vars:
AIRFLOW_CTX_DAG_OWNER=udacity
AIRFLOW_CTX_DAG_ID=udac_example_dag
AIRFLOW_CTX_TASK_ID=load_songplays_fact_table
AIRFLOW_CTX_EXECUTION_DATE=2022-03-17T04:00:00+00:00
AIRFLOW_CTX_DAG_RUN_ID=scheduled__2022-03-17T04:00:00+00:00
[2022-03-17 13:39:04,652] {load_fact.py:84} INFO - Starting to truncate songplays
[2022-03-17 13:39:04,660] {base.py:70} INFO - Using connection to: id: redshift. Host: redshift-cluster-1.cvmsgkpkbsh2.us-west-2.redshift.amazonaws.com, Port: 5439, Schema: dev, Login: awsuser, Password: ***, extra: {}
[2022-03-17 13:39:06,915] {dbapi.py:225} INFO - Running statement: 
        TRUNCATE TABLE "public"."songplays"
        , parameters: None
[2022-03-17 13:39:07,875] {load_fact.py:93} INFO - Starting to insert songplays
[2022-03-17 13:39:07,875] {taskinstance.py:1718} ERROR - Task failed with exception
Traceback (most recent call last):
  File "/usr/local/anaconda3/envs/data_pipeline/lib/python3.8/site-packages/airflow/models/taskinstance.py", line 1334, in _run_raw_task
    self._execute_task_with_callbacks(context)
  File "/usr/local/anaconda3/envs/data_pipeline/lib/python3.8/site-packages/airflow/models/taskinstance.py", line 1460, in _execute_task_with_callbacks
    result = self._execute_task(context, self.task)
  File "/usr/local/anaconda3/envs/data_pipeline/lib/python3.8/site-packages/airflow/models/taskinstance.py", line 1516, in _execute_task
    result = execute_callable(context=context)
  File "/Users/oneforall_nick/workspace/airflow/plugins/operators/load_fact.py", line 70, in execute
    self.load_songplays_fact_table(redshift_hook)
  File "/Users/oneforall_nick/workspace/airflow/plugins/operators/load_fact.py", line 95, in load_songplays_fact_table
    insert_fact_data = LoadFactOperator.insert_table.format(
KeyError: '(column_name)'
[2022-03-17 13:39:07,891] {taskinstance.py:1272} INFO - Marking task as FAILED. dag_id=udac_example_dag, task_id=load_songplays_fact_table, execution_date=20220317T040000, start_date=20220317T053904, end_date=20220317T053907
[2022-03-17 13:39:07,901] {standard_task_runner.py:89} ERROR - Failed to execute job 15 for task load_songplays_fact_table
Traceback (most recent call last):
  File "/usr/local/anaconda3/envs/data_pipeline/lib/python3.8/site-packages/airflow/task/task_runner/standard_task_runner.py", line 85, in _start_by_fork
    args.func(args, dag=self.dag)
  File "/usr/local/anaconda3/envs/data_pipeline/lib/python3.8/site-packages/airflow/cli/cli_parser.py", line 48, in command
    return func(*args, **kwargs)
  File "/usr/local/anaconda3/envs/data_pipeline/lib/python3.8/site-packages/airflow/utils/cli.py", line 92, in wrapper
    return f(*args, **kwargs)
  File "/usr/local/anaconda3/envs/data_pipeline/lib/python3.8/site-packages/airflow/cli/commands/task_command.py", line 298, in task_run
    _run_task_by_selected_method(args, dag, ti)
  File "/usr/local/anaconda3/envs/data_pipeline/lib/python3.8/site-packages/airflow/cli/commands/task_command.py", line 107, in _run_task_by_selected_method
    _run_raw_task(args, ti)
  File "/usr/local/anaconda3/envs/data_pipeline/lib/python3.8/site-packages/airflow/cli/commands/task_command.py", line 180, in _run_raw_task
    ti._run_raw_task(
  File "/usr/local/anaconda3/envs/data_pipeline/lib/python3.8/site-packages/airflow/utils/session.py", line 70, in wrapper
    return func(*args, session=session, **kwargs)
  File "/usr/local/anaconda3/envs/data_pipeline/lib/python3.8/site-packages/airflow/models/taskinstance.py", line 1334, in _run_raw_task
    self._execute_task_with_callbacks(context)
  File "/usr/local/anaconda3/envs/data_pipeline/lib/python3.8/site-packages/airflow/models/taskinstance.py", line 1460, in _execute_task_with_callbacks
    result = self._execute_task(context, self.task)
  File "/usr/local/anaconda3/envs/data_pipeline/lib/python3.8/site-packages/airflow/models/taskinstance.py", line 1516, in _execute_task
    result = execute_callable(context=context)
  File "/Users/oneforall_nick/workspace/airflow/plugins/operators/load_fact.py", line 70, in execute
    self.load_songplays_fact_table(redshift_hook)
  File "/Users/oneforall_nick/workspace/airflow/plugins/operators/load_fact.py", line 95, in load_songplays_fact_table
    insert_fact_data = LoadFactOperator.insert_table.format(
KeyError: '(column_name)'
[2022-03-17 13:39:07,941] {local_task_job.py:154} INFO - Task exited with return code 1
[2022-03-17 13:39:07,975] {local_task_job.py:264} INFO - 0 downstream tasks scheduled from follow-on schedule check
