[2022-03-17 10:27:01,246] {taskinstance.py:1037} INFO - Dependencies all met for <TaskInstance: udac_example_dag.task_loadDataFromS3ToTrips.Stage_events scheduled__2022-03-17T01:00:00+00:00 [queued]>
[2022-03-17 10:27:01,254] {taskinstance.py:1037} INFO - Dependencies all met for <TaskInstance: udac_example_dag.task_loadDataFromS3ToTrips.Stage_events scheduled__2022-03-17T01:00:00+00:00 [queued]>
[2022-03-17 10:27:01,254] {taskinstance.py:1243} INFO - 
--------------------------------------------------------------------------------
[2022-03-17 10:27:01,254] {taskinstance.py:1244} INFO - Starting attempt 2 of 3
[2022-03-17 10:27:01,255] {taskinstance.py:1245} INFO - 
--------------------------------------------------------------------------------
[2022-03-17 10:27:01,261] {taskinstance.py:1264} INFO - Executing <Task(StageToRedshiftOperator): task_loadDataFromS3ToTrips.Stage_events> on 2022-03-17 01:00:00+00:00
[2022-03-17 10:27:01,263] {standard_task_runner.py:52} INFO - Started process 18945 to run task
[2022-03-17 10:27:01,272] {standard_task_runner.py:76} INFO - Running: ['***', 'tasks', 'run', 'udac_example_dag', 'task_loadDataFromS3ToTrips.Stage_events', 'scheduled__2022-03-17T01:00:00+00:00', '--job-id', '5', '--raw', '--subdir', 'DAGS_FOLDER/udac_example_dag.py', '--cfg-path', '/var/folders/lh/ngst1lt51m9_gyz7qrg2f3nh0000gn/T/tmpis1kasnx', '--error-file', '/var/folders/lh/ngst1lt51m9_gyz7qrg2f3nh0000gn/T/tmplappnsog']
[2022-03-17 10:27:01,274] {standard_task_runner.py:77} INFO - Job 5: Subtask task_loadDataFromS3ToTrips.Stage_events
[2022-03-17 10:27:01,331] {logging_mixin.py:109} INFO - Running <TaskInstance: udac_example_dag.task_loadDataFromS3ToTrips.Stage_events scheduled__2022-03-17T01:00:00+00:00 [running]> on host 1.0.0.127.in-addr.arpa
[2022-03-17 10:27:01,376] {taskinstance.py:1429} INFO - Exporting the following env vars:
AIRFLOW_CTX_DAG_OWNER=udacity
AIRFLOW_CTX_DAG_ID=udac_example_dag
AIRFLOW_CTX_TASK_ID=task_loadDataFromS3ToTrips.Stage_events
AIRFLOW_CTX_EXECUTION_DATE=2022-03-17T01:00:00+00:00
AIRFLOW_CTX_DAG_RUN_ID=scheduled__2022-03-17T01:00:00+00:00
[2022-03-17 10:27:01,377] {stage_redshift.py:75} INFO - Starting to set aws redshift connection
[2022-03-17 10:27:01,384] {base_aws.py:190} INFO - Credentials retrieved from login
[2022-03-17 10:27:01,395] {stage_redshift.py:79} INFO - Starting to truncate table, table name: events!
[2022-03-17 10:27:01,396] {stage_redshift.py:144} INFO - Starting to execute the truncate_table_sql process
[2022-03-17 10:27:01,403] {base.py:70} INFO - Using connection to: id: redshift. Host: redshift-cluster-1.cvmsgkpkbsh2.us-west-2.redshift.amazonaws.com, Port: 5439, Schema: dev, Login: awsuser, Password: ***, extra: {}
[2022-03-17 10:27:03,652] {dbapi.py:225} INFO - Running statement: 
        TRUNCATE TABLE public.events
        , parameters: None
[2022-03-17 10:27:04,292] {taskinstance.py:1718} ERROR - Task failed with exception
Traceback (most recent call last):
  File "/usr/local/anaconda3/envs/data_pipeline/lib/python3.8/site-packages/airflow/models/taskinstance.py", line 1334, in _run_raw_task
    self._execute_task_with_callbacks(context)
  File "/usr/local/anaconda3/envs/data_pipeline/lib/python3.8/site-packages/airflow/models/taskinstance.py", line 1460, in _execute_task_with_callbacks
    result = self._execute_task(context, self.task)
  File "/usr/local/anaconda3/envs/data_pipeline/lib/python3.8/site-packages/airflow/models/taskinstance.py", line 1516, in _execute_task
    result = execute_callable(context=context)
  File "/Users/oneforall_nick/workspace/airflow/plugins/operators/stage_redshift.py", line 80, in execute
    self.truncate_stage_table(redshift_hook)
  File "/Users/oneforall_nick/workspace/airflow/plugins/operators/stage_redshift.py", line 150, in truncate_stage_table
    redshift_hook.run(truncate_table_sql)
  File "/usr/local/anaconda3/envs/data_pipeline/lib/python3.8/site-packages/airflow/hooks/dbapi.py", line 205, in run
    self._run_command(cur, sql_statement, parameters)
  File "/usr/local/anaconda3/envs/data_pipeline/lib/python3.8/site-packages/airflow/hooks/dbapi.py", line 229, in _run_command
    cur.execute(sql_statement)
psycopg2.errors.UndefinedTable: relation "public.events" does not exist

[2022-03-17 10:27:04,306] {taskinstance.py:1272} INFO - Marking task as UP_FOR_RETRY. dag_id=udac_example_dag, task_id=task_loadDataFromS3ToTrips.Stage_events, execution_date=20220317T010000, start_date=20220317T022701, end_date=20220317T022704
[2022-03-17 10:27:04,316] {standard_task_runner.py:89} ERROR - Failed to execute job 5 for task task_loadDataFromS3ToTrips.Stage_events
Traceback (most recent call last):
  File "/usr/local/anaconda3/envs/data_pipeline/lib/python3.8/site-packages/airflow/task/task_runner/standard_task_runner.py", line 85, in _start_by_fork
    args.func(args, dag=self.dag)
  File "/usr/local/anaconda3/envs/data_pipeline/lib/python3.8/site-packages/airflow/cli/cli_parser.py", line 48, in command
    return func(*args, **kwargs)
  File "/usr/local/anaconda3/envs/data_pipeline/lib/python3.8/site-packages/airflow/utils/cli.py", line 92, in wrapper
    return f(*args, **kwargs)
  File "/usr/local/anaconda3/envs/data_pipeline/lib/python3.8/site-packages/airflow/cli/commands/task_command.py", line 298, in task_run
    _run_task_by_selected_method(args, dag, ti)
  File "/usr/local/anaconda3/envs/data_pipeline/lib/python3.8/site-packages/airflow/cli/commands/task_command.py", line 107, in _run_task_by_selected_method
    _run_raw_task(args, ti)
  File "/usr/local/anaconda3/envs/data_pipeline/lib/python3.8/site-packages/airflow/cli/commands/task_command.py", line 180, in _run_raw_task
    ti._run_raw_task(
  File "/usr/local/anaconda3/envs/data_pipeline/lib/python3.8/site-packages/airflow/utils/session.py", line 70, in wrapper
    return func(*args, session=session, **kwargs)
  File "/usr/local/anaconda3/envs/data_pipeline/lib/python3.8/site-packages/airflow/models/taskinstance.py", line 1334, in _run_raw_task
    self._execute_task_with_callbacks(context)
  File "/usr/local/anaconda3/envs/data_pipeline/lib/python3.8/site-packages/airflow/models/taskinstance.py", line 1460, in _execute_task_with_callbacks
    result = self._execute_task(context, self.task)
  File "/usr/local/anaconda3/envs/data_pipeline/lib/python3.8/site-packages/airflow/models/taskinstance.py", line 1516, in _execute_task
    result = execute_callable(context=context)
  File "/Users/oneforall_nick/workspace/airflow/plugins/operators/stage_redshift.py", line 80, in execute
    self.truncate_stage_table(redshift_hook)
  File "/Users/oneforall_nick/workspace/airflow/plugins/operators/stage_redshift.py", line 150, in truncate_stage_table
    redshift_hook.run(truncate_table_sql)
  File "/usr/local/anaconda3/envs/data_pipeline/lib/python3.8/site-packages/airflow/hooks/dbapi.py", line 205, in run
    self._run_command(cur, sql_statement, parameters)
  File "/usr/local/anaconda3/envs/data_pipeline/lib/python3.8/site-packages/airflow/hooks/dbapi.py", line 229, in _run_command
    cur.execute(sql_statement)
psycopg2.errors.UndefinedTable: relation "public.events" does not exist

[2022-03-17 10:27:04,346] {local_task_job.py:154} INFO - Task exited with return code 1
[2022-03-17 10:27:04,378] {local_task_job.py:264} INFO - 0 downstream tasks scheduled from follow-on schedule check
